{
  "comments": [
    {
      "unresolved": false,
      "key": {
        "uuid": "0d584323_bf7621f5",
        "filename": "/PATCHSET_LEVEL",
        "patchSetId": 1
      },
      "lineNbr": 0,
      "author": {
        "id": 558
      },
      "writtenOn": "2023-02-20T09:54:04Z",
      "side": 1,
      "message": "recheck",
      "revId": "1d9adca88f47e539f24067a04b1a5261d6ed68c6",
      "serverId": "270e2033-b340-4cff-9539-693957ebf0e7"
    },
    {
      "unresolved": false,
      "key": {
        "uuid": "deb4a206_db6b0290",
        "filename": "/PATCHSET_LEVEL",
        "patchSetId": 1
      },
      "lineNbr": 0,
      "author": {
        "id": 558
      },
      "writtenOn": "2023-02-22T13:05:34Z",
      "side": 1,
      "message": "looks like an issue with the order of a test result\ntrying to see if we can easily fix that\nbtw we removed support for Python 3.6 eight months ago",
      "revId": "1d9adca88f47e539f24067a04b1a5261d6ed68c6",
      "serverId": "270e2033-b340-4cff-9539-693957ebf0e7"
    }
  ]
}